Workbook

Sheet 안내
A1: 실라버스 v10 — 틀 (초안)
A2: 구조: 시작 → 온톨로지 → 에이전트 → BPMN → 마무리. 막마다 이론 → 포털(사건 A · B · C) → 랩업 순서로 고정.
A3: 이론 = 포털 · 랩업을 위한 준비(필요한 개념과 앞으로 할 일을 비유로 쉽게). 외부 서비스는 arrows.app · bpmn.io만, 설명만인 행도 있음.
A4: 포털 = 강사를 따라 차근차근, 단계 사이마다 설명. 랩업 = 바이브 코딩으로 한 번 더, 설명 계속 · 실수와 복구 시간 포함.
A5: 전제: 기능은 구현됐다고 치고 짠 틀. 사건 A 긴급 대응 · B 정비 계획 · C 예비품 구매는 확정 전(시나리오 재조사 중)이라 B · C 행 내용은 바뀔 수 있음.
A7: 시트
A8: 실라버스 — 행 목록. 통합 영상 · 통합 오프 시간은 '시간 근거' 시트 부품의 합(수식). 실전 영상 · 실전 오프는 입력값(파란 글씨).
A9: 막별 합계 — 막별 시간, 고정 합계와 차이, 세 막 비율(목표 40 : 35 : 25). 고정 합계는 입력값(파란 글씨).
A10: 시간 근거 — 행마다 부품(설명 · 따라 하기 · AI 대기 · 여유)과 분. 부품 분을 고치면 실라버스 · 막별 합계가 따라 바뀜.
A11: 근거 출처 — AI 대기 시간 등의 실측 출처.
A13: 고치는 곳
A14: 파란 글씨 칸만 고친다: '시간 근거'의 부품 분, '실라버스'의 실전 영상 · 실전 오프, '막별 합계'의 고정 합계. 검정 글씨는 수식.
... A17: 상세 근거와 조정안: docs/handoff/verification/2026-10-09/syllabus-v10.md (5절: 남는 · 모자란 시간과 조정안, 열린 결정).

Sheet 실라버스
A1: No | B1: 막 | C1: 구간 | D1: 행 ID | E1: 제목(가치 문장) | F1: 무엇을 하나(개념 · 비유 · 도구 · 사건) | G1: 준비하는 뒤 행 | H1: 통합 영상(분) | I1: 통합 오프(분) | J1: 실전 영상(분) | K1: 실전 오프(분) | L1: 실전에서 줄인 곳 | M1: AI 대기 근거
A2: 1 | B2: 시작 | C2: 시작 | D2: S1 | E2: 배운 것을 다음에 꺼내 쓰는 내 노트부터 만든다 — 지식 자산화 | F2: 왜 노트로 남기나(비유: 집집마다 다른 요리 노트) · Notion 첫 사용(로그인·화면) · 과정 노트 틀 복제(칸: 개념 · 결과 화면 · 막힌 곳 · 해결) · 첫 줄 쓰기 · 막마다 노트 쓰는 법 | H2: =SUMIF('시간 근거'!$A$2:$A$546,D2,'시간 근거'!$E$2:$E$546) -> 30 | I2: =SUMIF('시간 근거'!$A$2:$A$546,D2,'시간 근거'!$F$2:$F$546) -> 40 | J2: 25 | K2: 35 | L2: 사례를 줄임(왜 5분), 첫 기록 4분
A3: 2 | B3: 시작 | C3: 시작 | D3: S2 | E3: 앞 수업에서 본 센서 값의 길을 다시 걷는다 — SCADA 되짚기 | F3: 앞 과정 지도(설비 → PLC → 메시지 통로 → 시계열 DB → SCADA 화면) · 앞 수업 SCADA 화면(FUXA)과 포털 실시간 모니터링에서 같은 값 찾기 · 우리 공장 센서(유온 TS1 · 압력 PS1 · 유량 FS1 · 냉각 효율 CE) | H3: =SUMIF('시간 근거'!$A$2:$A$546,D3,'시간 근거'!$E$2:$E$546) -> 30 | I3: =SUMIF('시간 근거'!$A$2:$A$546,D3,'시간 근거'!$F$2:$F$546) -> 30 | J3: 25 | K3: 25 | L3: 지도 8 · 화면 8 · 센서 6 · 정리 3
A4: 3 | B4: 시작 | C4: 시작 | D4: S3 | E4: 센서 값 위에 지식 · AI · 업무가 층층이 올라간다 — 이 포털의 구조 | F4: 비유: 건물 층(설비 · 데이터 / 지식 / AI 일꾼 / 업무 흐름 / 화면) · 층마다 이번 과정의 어느 막인가 · 층 사이에 오가는 것(값 · 질문 · 제안 · 승인) · 세 사건이 층을 지나가는 모습 | H4: =SUMIF('시간 근거'!$A$2:$A$546,D4,'시간 근거'!$E$2:$E$546) -> 30 | I4: =SUMIF('시간 근거'!$A$2:$A$546,D4,'시간 근거'!$F$2:$F$546) -> 25 | J4: 25 | K4: 25 | L4: 층 설명을 줄임
A5: 4 | B5: 시작 | C5: 시작 | D5: S4 | E5: 값 하나가 태어나 업무 한 건이 되기까지 따라간다 — 데이터 리니지 | F5: 비유: 택배 송장 추적 · 출생 → 변환 → 저장 → 소비 · 유온 TS1 하나가 경보 → 처리 건 → 작업지시 기록이 되는 길(종이에 그리기) · 실패 · 분기(늦게 오면? 끊기면?) | H5: =SUMIF('시간 근거'!$A$2:$A$546,D5,'시간 근거'!$E$2:$E$546) -> 30 | I5: =SUMIF('시간 근거'!$A$2:$A$546,D5,'시간 근거'!$F$2:$F$546) -> 30 | J5: 25 | K5: 25 | L5: 종이 그리기를 강사 판서로
A6: 5 | B6: 시작 | C6: 시작 | D6: S5 | E6: 경보 한 건이 승인 · 실행 · 확인까지 닫히는 것을 먼저 끝까지 본다 — 우리가 만들 것과 포털 둘러보기 | F6: 세 사건 한 줄 이야기(A 쿨러 과열 · B 펌프 효율 저하 · C 씰 키트 재고 부족) · 최종 목표 시연 A 끝까지 · 포털 메뉴 둘러보기 · 기준으로 되돌리기 · "이것을 막마다 하나씩 만든다" | H6: =SUMIF('시간 근거'!$A$2:$A$546,D6,'시간 근거'!$E$2:$E$546) -> 30 | I6: =SUMIF('시간 근거'!$A$2:$A$546,D6,'시간 근거'!$F$2:$F$546) -> 35 | J6: 25 | K6: 30 | L6: 메뉴 둘러보기 4분, 소개 3분 | M6: RAISE · W4 · REOBS · CASE
A7: 6 | B7: 온톨로지 | C7: 이론 | D7: OT1 | E7: AI는 책을 많이 읽었지만 우리 공장은 모른다 — 언어 모델이 무엇이고 왜 그럴듯하게 틀리나 | F7: 막 여는 이야기(세 사건이 이 막에서 얻을 것: 문서 → 지식) · 비유: 책 수백만 권을 읽은 신입 · 다음 말 맞히기 · 배운 것 밖은 모름 · 그럴듯한 틀린 답(환각) 사례 · 공장에서 틀리면 생기는 일 · 설명만 | G7: OL2 · AP1 · AL1 | H7: =SUMIF('시간 근거'!$A$2:$A$546,D7,'시간 근거'!$E$2:$E$546) -> 30 | I7: =SUMIF('시간 근거'!$A$2:$A$546,D7,'시간 근거'!$F$2:$F$546) -> 30 | J7: 25 | K7: 25 | L7: 사례 하나로 줄임
A8: 7 | B8: 온톨로지 | C8: 이론 | D8: OT2 | E8: 내 문서를 찾아 붙여 주면 AI가 근거를 들고 답한다 — 찾아서 답하기 | F8: 비유: 도서관 사서가 책을 찾아 펼쳐 준다 · 뜻이 가까운 글을 찾는 법(그림) · 찾아 붙여 답하는 순서 · 근거 인용과 한계(문서에 없으면 모른다고 해야) · 설명만 | G8: OP2 꼭 답할 질문 · OL2 | H8: =SUMIF('시간 근거'!$A$2:$A$546,D8,'시간 근거'!$E$2:$E$546) -> 30 | I8: =SUMIF('시간 근거'!$A$2:$A$546,D8,'시간 근거'!$F$2:$F$546) -> 30 | J8: 25 | K8: 25 | L8: 그림 설명을 줄임
A9: 8 | B9: 온톨로지 | C9: 이론 | D9: OT3 | E9: 사물과 관계를 이은 지도는 문서가 못 하는 "연결"에 답한다 — 지식 그래프(온톨로지) | F9: 비유: 지하철 노선도(역 = 사물, 선 = 관계) · 무엇 · 문서 검색과 지도 비교 예("이 부품이 멈추면 어느 설비 · 어느 주문이 늦나") · 공장에 쓰면 · 설명만 | G9: OP2 · OP4 · OL3 | H9: =SUMIF('시간 근거'!$A$2:$A$546,D9,'시간 근거'!$E$2:$E$546) -> 30 | I9: =SUMIF('시간 근거'!$A$2:$A$546,D9,'시간 근거'!$F$2:$F$546) -> 30 | J9: 25 | K9: 25 | L9: 비교 예 하나로
A10: 9 | B10: 온톨로지 | C10: 이론 | D10: OT4 | E10: 틀(스키마)과 내용을 나눠 적으면 누구나 같은 모양으로 지식을 쌓는다 — 클래스 · 속성 · 관계 | F10: 비유: 주소록 양식과 적힌 이름 · 클래스 · 속성 · 관계, 틀과 내용 · arrows.app 첫 사용(노드 · 관계 · 속성 · 내보내기) · 동네 카페(손님 – 주문 – 메뉴) 관계도 그리기 · 속성으로 둘까 관계로 둘까 | G10: OP1~OP4 지식 지도 읽기 · OL3 틀 세우기 | H10: =SUMIF('시간 근거'!$A$2:$A$546,D10,'시간 근거'!$E$2:$E$546) -> 30 | I10: =SUMIF('시간 근거'!$A$2:$A$546,D10,'시간 근거'!$F$2:$F$546) -> 50 | J10: 25 | K10: 40 | L10: arrows.app는 따라 그리기 한 번(영상 20분 분량 + 정리), 오프는 설명 20 + 해보기 20
A11: 10 | B11: 온톨로지 | C11: 이론 | D11: OT5 | E11: 지도를 손가락으로 따라가듯 질문한다 — 지식 지도에 묻기 | F11: 비유: 길찾기 앱(출발 → 환승 → 도착) · 질문의 모양(그림으로 묻기: 손님 –주문→ 메뉴) · OT4에서 그린 arrows.app 관계도로 질문 따라가기(두 번째 사용) · 표로 찾을 때와 비교 | G11: OP2 · OL9 · OL10 | H11: =SUMIF('시간 근거'!$A$2:$A$546,D11,'시간 근거'!$E$2:$E$546) -> 30 | I11: =SUMIF('시간 근거'!$A$2:$A$546,D11,'시간 근거'!$F$2:$F$546) -> 35 | J11: 20 | K11: 30 | L11: 비교를 짧게
A12: 11 | B12: 온톨로지 | C12: 이론 | D12: OT6 | E12: 병원이 진료하듯 고장을 다룬다 — 증상 · 고장 · 원인 · 조치, 그리고 미리 알아채기 | F12: 비유: 병원 진료(문진 → 검사 → 진단 → 경과 예측 → 처방) · 관측 → 상태 → 진단 → 예측 → 권고 · 미리 알아채기(P-F 간격) · 정비 종류 셋(바로 고치기 · 계획해서 고치기 · 부품 미리 사 두기 = 사건 A · B · C) · 종이 카드: 자전거 브레이크 소리 | G12: OP1~OP4 · AP2~AP4 · BP3 | H12: =SUMIF('시간 근거'!$A$2:$A$546,D12,'시간 근거'!$E$2:$E$546) -> 30 | I12: =SUMIF('시간 근거'!$A$2:$A$546,D12,'시간 근거'!$F$2:$F$546) -> 40 | J12: 25 | K12: 35 | L12: 카드 활동을 강사 시연으로(오프는 모둠 10)
A13: 12 | B13: 온톨로지 | C13: 이론 | D13: OT7 | E13: 순서를 적은 것과 판단을 적은 것을 나눈다 — 절차(SOP)와 판단 규칙표 | F13: 비유: 레시피(순서) vs 식당 할인 규칙표(조건 → 결정) · 절차의 모양(순서 · 조건 · 금지) · 규칙표의 모양(입력 · 출력 · 규칙 줄) · demo.bpmn.io DMN 첫 사용 · 카페 할인 규칙 세 줄 | G13: OP1 검토(절차 · 규칙) · AT6 · AL6 | H13: =SUMIF('시간 근거'!$A$2:$A$546,D13,'시간 근거'!$E$2:$E$546) -> 30 | I13: =SUMIF('시간 근거'!$A$2:$A$546,D13,'시간 근거'!$F$2:$F$546) -> 45 | J13: 25 | K13: 40 | L13: 세 줄 만들기를 한 줄로
A14: 13 | B14: 온톨로지 | C14: 이론 | D14: OT8 | E14: 회사가 무엇을 중요하게 보는지 알아야 조치를 고를 수 있다 — 네 관점 지표와 서로 부딪히는 지표(BSC) | F14: 비유: 건강검진 네 영역 · 재무 · 고객 · 내부 프로세스 · 학습과 성장, 원인 → 결과 화살표 · 동네 카페 전략맵 읽기 · 종이 전략맵 그리기(모둠) · 상충 찾기(빨리 내기 vs 맛, 싼 원두 vs 불만) · 공장 지표 미리보기(납기 · 가동률 · 영업이익) | G14: OP2 · OP4 · OL9 · AP2 손익 | H14: =SUMIF('시간 근거'!$A$2:$A$546,D14,'시간 근거'!$E$2:$E$546) -> 30 | I14: =SUMIF('시간 근거'!$A$2:$A$546,D14,'시간 근거'!$F$2:$F$546) -> 50 | J14: 25 | K14: 40 | L14: 전략맵 그리기를 반쯤 그린 판으로(12분)
A15: 14 | B15: 온톨로지 | C15: 이론 | D15: OT9 | E15: 긴 문서가 지식이 되는 길 — 나누고, 뽑고, 틀에 맞추고, 근거를 남기고, 사람이 확인한다 | F15: 비유: 요리책에서 레시피 카드를 뽑아 정리함에 꽂기 · 다섯 단계 · 왜 나누나(한 번에 읽는 양에 한계 — 비유: 한 번에 외울 수 있는 쪽수) · 종이 형광펜(커피머신 설명서: 조건 · 순서 · 금지) · AI가 뽑은 표를 원문과 대조하는 법(종이) · 왜 사람이 확인하나 | G15: OP1 · OP3 · OP4 검토 · OL5~OL7 | H15: =SUMIF('시간 근거'!$A$2:$A$546,D15,'시간 근거'!$E$2:$E$546) -> 30 | I15: =SUMIF('시간 근거'!$A$2:$A$546,D15,'시간 근거'!$F$2:$F$546) -> 45 | J15: 25 | K15: 40 | L15: 형광펜 · 대조를 시연 위주로
A16: 15 | B16: 온톨로지 | C16: 이론 | D16: OT10 | E16: 값은 지식에 넣지 않고 자리만 적고, 지식이 맞는지는 꼭 답할 질문으로 안다 | F16: 비유: 도서관 색인 카드(책이 아니라 위치) · 값 vs 자리("내 주문 배송 상태는 어느 표 어느 칸") · 비유: 시험 문제를 먼저 정해 두기 · 꼭 답할 질문 쓰기 · 내 arrows.app 관계도에서 관계 하나 지우면 답이 바뀌나 | G16: OP2 · OP3 · OL8 · OL10 | H16: =SUMIF('시간 근거'!$A$2:$A$546,D16,'시간 근거'!$E$2:$E$546) -> 30 | I16: =SUMIF('시간 근거'!$A$2:$A$546,D16,'시간 근거'!$F$2:$F$546) -> 35 | J16: 25 | K16: 30 | L16: 지우기 실험을 시연으로
A17: 16 | B17: 온톨로지 | C17: 이론 | D17: OR | E17: 지금까지 배운 것 — 포털에 들어가기 전 한 장으로 | F17: 열 가지 개념을 한 장 그림으로 · 포털에서 각각 어디에 보이는지 예고 | H17: =SUMIF('시간 근거'!$A$2:$A$546,D17,'시간 근거'!$E$2:$E$546) -> 10 | I17: =SUMIF('시간 근거'!$A$2:$A$546,D17,'시간 근거'!$F$2:$F$546) -> 10 | J17: 10 | K17: 10 | L17: 같음
A18: 17 | B18: 온톨로지 | C18: 포털 | D18: OP1 | E18: 쿨러 과열 문서를 넣기 전에는 "근거 없음"이던 경보가, 넣은 뒤에는 원인과 조치를 갖는다 (A ① 넣기 → 검토 → 등록) | F18: A 처음이라 천천히. 화면 안내 · 적재 전 경보(보류 사유) · A 문서 함께 읽기(판정 기준 · 원인 3 · 완화 절차 3 · 근본 절차 2 · 금지) · 넣기 · 추출 과정 화면 · 자동 표시 항목만 원문 대조 · 등록 · 새 노드. 다시 설명하는 개념: 근거 없으면 멈춤 · 틀의 칸(OT4) · 인제스천 다섯 단계(OT9) · 사람 확인 | H18: =SUMIF('시간 근거'!$A$2:$A$546,D18,'시간 근거'!$E$2:$E$546) -> 30 | I18: =SUMIF('시간 근거'!$A$2:$A$546,D18,'시간 근거'!$F$2:$F$546) -> 40 | J18: 25 | K18: 35 | L18: 문서 읽기 · 설명을 짧게 | M18: RAISE · EXT
A19: 18 | B19: 온톨로지 | C19: 포털 | D19: OP2 | E19: 쿨러 과열 지식의 길을 끝까지 따라간다 — 경보에서 원인, 조치, 회사 이익까지 (A ② 길 따라가기 · 꼭 답할 질문) | F19: 지식 지도 조작 · 경보 → 증상 → 원인 → 증거 · 조치(SOP-COOL) → 명령 값 → 납기 · 전력비 → 영업이익 · 꼭 답할 질문 3개. 다시 설명: 클래스 · 관계(OT4) · 진료 순서(OT6) · 전략맵 화살표(OT8) · 질문이 검사가 되는 이유(OT10) | H19: =SUMIF('시간 근거'!$A$2:$A$546,D19,'시간 근거'!$E$2:$E$546) -> 30 | I19: =SUMIF('시간 근거'!$A$2:$A$546,D19,'시간 근거'!$F$2:$F$546) -> 35 | J19: 25 | K19: 30 | L19: 설명 셋을 하나로 | M19: GQ
A20: 19 | B20: 온톨로지 | C20: 포털 | D20: OP3 | E20: 펌프 문서를 넣으면 "언제 세워서 고칠까"를 판단할 지식이 생긴다 (B 넣기 → 등록 → 길 · 질문, 빠르게) | F20: 두 번째라 빠르게. B 문서(판정표 · P점 · 정비 시점 판단 · 압력 상향 금지) · 검토(금지 규칙) · 길: 증상 → 원인(씰 마모) → 부품(씰 키트) → "남은 시간 < 리드타임" 규칙. 다시 설명: 미리 알아채기 P점(OT6) · 금지 규칙(OT7) · 값은 자리만(OT10) | H20: =SUMIF('시간 근거'!$A$2:$A$546,D20,'시간 근거'!$E$2:$E$546) -> 30 | I20: =SUMIF('시간 근거'!$A$2:$A$546,D20,'시간 근거'!$F$2:$F$546) -> 35 | J20: 25 | K20: 30 | L20: 설명을 짧게 | M20: EXT · GQ
A21: 20 | B21: 온톨로지 | C21: 포털 | D21: OP4 | E21: 구매 기준 문서를 넣으면 부품 · 공급사 · 금액 규칙이 한 지도에 이어진다 (C, 빠르게 · 세 지식 나란히) | F21: 세 번째. C 문서(재주문점 · 승인 공급사 · 300만 원 전결) · 길: 씰 키트 → 쓰이는 설비 · 고장 → 공급사 셋(단가 · 불량률 · 리드타임 · 승인 여부) → 상충 → 규정 · A · B · C 세 지식 나란히. 다시 설명: 재주문점 · 전결 · 상충(OT8) · "틀은 같고 내용이 다르다"(OT4) | H21: =SUMIF('시간 근거'!$A$2:$A$546,D21,'시간 근거'!$E$2:$E$546) -> 30 | I21: =SUMIF('시간 근거'!$A$2:$A$546,D21,'시간 근거'!$F$2:$F$546) -> 35 | J21: 25 | K21: 30 | L21: 세 지식 비교를 짧게 | M21: EXT · GQ
A22: 21 | B22: 온톨로지 | C22: 랩업 | D22: OL1 | E22: 말로 시켜 만드는 조수와 처음 일한다 — 작업 폴더를 열고 첫 결과를 본다 | F22: 바이브 코딩(말로 시키고 결과를 확인) · VS Code · 터미널 · Claude Code 첫 사용 · "고쳐도 되나" 물음 읽는 법 · 출발본으로 되돌리기. 출발본: 온톨로지 트랙 폴더 + 첫 지시문 예. 다시 설명: 언어 모델(OT1) — 이제 직접 써 본다 | H22: =SUMIF('시간 근거'!$A$2:$A$546,D22,'시간 근거'!$E$2:$E$546) -> 45 | I22: =SUMIF('시간 근거'!$A$2:$A$546,D22,'시간 근거'!$F$2:$F$546) -> 50 | J22: 40 | K22: 45 | L22: 둘러보기 · 정리를 짧게 | M22: CC
A23: 22 | B23: 온톨로지 | C23: 랩업 | D23: OL2 | E23: 매뉴얼을 찾아 함께 넣어 주면 AI의 답에 근거 구절이 붙는다 | F23: L1 · 만들 것: A 문서에서 관련 절을 찾아 답과 근거 줄을 내는 작은 프로그램 · 볼 결과: 문서 없을 때와 있을 때 답 비교 · 포털: 지식 관리 "이 문서로 답할 수 있는 질문" · 출발본: A 문서 텍스트 + 질문 3개. 다시 설명: 환각(OT1) · 찾아서 답하기(OT2) | H23: =SUMIF('시간 근거'!$A$2:$A$546,D23,'시간 근거'!$E$2:$E$546) -> 40 | I23: =SUMIF('시간 근거'!$A$2:$A$546,D23,'시간 근거'!$F$2:$F$546) -> 45 | J23: 35 | K23: 40 | L23: 쉬운 말 읽기 · 정리를 줄임 | M23: CC · GQ
A24: 23 | B24: 온톨로지 | C24: 랩업 | D24: OL3 | E24: 증상 · 고장 · 원인 · 조치 · 지표의 틀을 직접 세운다 | F24: L2 · L3 · 만들 것: 틀 설명 1쪽 → 그래프 DB의 클래스 · 관계 · 제약 · 볼 결과: Neo4j Browser 그림 · 포털: 지식 지도의 클래스 구성 · 출발본: 빈 그래프 DB + 틀 설명 1쪽. 다시 설명: 클래스 · 속성 · 관계(OT4) · 증상 · 고장 · 원인 · 조치(OT6) | H24: =SUMIF('시간 근거'!$A$2:$A$546,D24,'시간 근거'!$E$2:$E$546) -> 45 | I24: =SUMIF('시간 근거'!$A$2:$A$546,D24,'시간 근거'!$F$2:$F$546) -> 50 | J24: 40 | K24: 45 | L24: Neo4j Browser 안내를 짧게 | M24: CC
A25: 24 | B25: 온톨로지 | C25: 랩업 | D25: OL4 | E25: 공장 구조를 틀에 채운다 — 두 번 넣어도 같은 결과가 나와야 믿을 수 있다 | F25: L4 · 만들 것: 설비 3대 · 부품 · 센서 CSV 적재기 · 볼 결과: 두 번 넣어도 노드 수 그대로(중복 = 잘못된 판단) · 포털: 지식 적재(구조) · 출발본: CSV 몇 줄. 다시 설명: 틀과 내용(OT4) | H25: =SUMIF('시간 근거'!$A$2:$A$546,D25,'시간 근거'!$E$2:$E$546) -> 40 | I25: =SUMIF('시간 근거'!$A$2:$A$546,D25,'시간 근거'!$F$2:$F$546) -> 45 | J25: 35 | K25: 40 | L25: 같은 방식으로 줄임 | M25: CC
A26: 25 | B26: 온톨로지 | C26: 랩업 | D26: OL5 | E26: 긴 문서를 절차 중간에서 끊지 않고 나눈다 | F26: L9 · 만들 것: 절 단위 나누기 · 볼 결과: 조각과 경계, 실물 80쪽 사례(구간 2, 612초 — 녹화 압축) · 포털: 문서 적재의 구간 나누기 · 출발본: A · B 문서 텍스트. 다시 설명: 왜 나누나(OT9) | H26: =SUMIF('시간 근거'!$A$2:$A$546,D26,'시간 근거'!$E$2:$E$546) -> 45 | I26: =SUMIF('시간 근거'!$A$2:$A$546,D26,'시간 근거'!$F$2:$F$546) -> 50 | J26: 40 | K26: 45 | L26: 80쪽 사례를 짧게 | M26: CC · LONG
A27: 26 | B27: 온톨로지 | C27: 랩업 | D27: OL6 | E27: 조각에서 고장 · 원인 · 절차를 뽑되, 틀에 맞는 것만 원문 근거와 함께 남긴다 | F27: L10 · 만들 것: 조각 → 틀에 맞는 항목 추출 · 볼 결과: 틀 밖 항목 거절, 근거 구간 표시 · 포털: 추출 제안 · 출발본: OL5 조각 + OL3 틀. 다시 설명: 뽑기 · 틀 검사 · 근거(OT9) | H27: =SUMIF('시간 근거'!$A$2:$A$546,D27,'시간 근거'!$E$2:$E$546) -> 45 | I27: =SUMIF('시간 근거'!$A$2:$A$546,D27,'시간 근거'!$F$2:$F$546) -> 50 | J27: 40 | K27: 45 | L27: 추출을 1회로 | M27: CC · EXT
A28: 27 | B28: 온톨로지 | C28: 랩업 | D28: OL7 | E28: 사람이 확인한 것만 지식에 잇는다 — 검토하고, 고장에 연결하고, 등록하고, 되돌린다 | F28: 신규(검토 · 연결) · 만들 것: 검토 목록 → 승인한 것만 등록 → 고장 유형에 연결 · 볼 결과: 승인 안 한 항목은 안 들어감, 배치 되돌리기 · 포털: 검토 · 등록 화면 · 출발본: OL6 결과. 다시 설명: 사람 확인(OT9) · 관계(OT4) | H28: =SUMIF('시간 근거'!$A$2:$A$546,D28,'시간 근거'!$E$2:$E$546) -> 40 | I28: =SUMIF('시간 근거'!$A$2:$A$546,D28,'시간 근거'!$F$2:$F$546) -> 45 | J28: 35 | K28: 40 | L28: 같은 방식 | M28: CC
A29: 28 | B29: 온톨로지 | C29: 랩업 | D29: OL8 | E29: 정비창 · 재고 · 공급 조건 값은 업무 DB에 두고, 지식에는 자리만 잇는다 | F29: L11 · 만들 것: 업무 DB 표 구조(DDL) → "이 값은 이 표 이 칸" 연결 · 볼 결과: 지식에 값 없이 자리만, 조회 결과 · 포털: 지식 관리 › 업무 데이터 연결 · 출발본: 표 구조 파일. 다시 설명: 값 vs 자리(OT10) | H29: =SUMIF('시간 근거'!$A$2:$A$546,D29,'시간 근거'!$E$2:$E$546) -> 40 | I29: =SUMIF('시간 근거'!$A$2:$A$546,D29,'시간 근거'!$F$2:$F$546) -> 45 | J29: 35 | K29: 40 | L29: 같은 방식 | M29: CC
... A31: 30 | B31: 온톨로지 | C31: 랩업 | D31: OL10 | E31: 꼭 답해야 할 질문으로 내 지식을 자동 검사한다 — 관계 하나를 끊으면 잡히는가 | F31: L6 · 만들 것: 질문 5개 자동 검사 · 볼 결과: 일부러 끊은 관계에서 검사 실패 → 고치면 통과 · 포털: 꼭 답해야 할 질문 · 트랙 한눈에(틀 → 적재 → 문서 → 추출 → 검토 → 자리 → 지표 → 검사). 다시 설명: 꼭 답할 질문(OT10) | H31: =SUMIF('시간 근거'!$A$2:$A$546,D31,'시간 근거'!$E$2:$E$546) -> 45 | I31: =SUMIF('시간 근거'!$A$2:$A$546,D31,'시간 근거'!$F$2:$F$546) -> 50 | J31: 40 | K31: 45 | L31: 트랙 정리를 짧게 | M31: CC · GQ
A32: 31 | B32: 에이전트 | C32: 이론 | D32: AT1 | E32: 답만 하는 AI와 일을 하는 AI는 다르다 — 에이전트 | F32: 막 여는 이야기(지식이 생겼다 → 이제 누가 그 지식으로 판단하나) · 비유: 전화 · 검색 · 예약을 직접 하는 비서 · 에이전트 = 언어 모델 + 도구 + 절차 + 목표 · 답만 하는 AI vs 도구를 부르는 AI 사례 그림 · 왜 공장에 필요한가 · 설명만 | G32: AP1 · AL1 | H32: =SUMIF('시간 근거'!$A$2:$A$546,D32,'시간 근거'!$E$2:$E$546) -> 30 | I32: =SUMIF('시간 근거'!$A$2:$A$546,D32,'시간 근거'!$F$2:$F$546) -> 30 | J32: 25 | K32: 25 | L32: 사례를 짧게
A33: 32 | B33: 에이전트 | C33: 이론 | D33: AT2 | E33: 보고, 생각하고, 움직이고, 다시 본다 — 몸으로 해 보는 AI 일꾼 | F33: 관찰 → 판단 → 행동 되풀이 · 역할극(동네 맛집 예약: 일꾼 1 · 도구 카드 3 · 승인자 1, 영상은 녹화) · 기록지(생각 · 행동 · 관찰) · 2라운드: 도구 카드 하나 빼면? | G33: AP1 질문하기 · AP2 · AL1 · BL4 | H33: =SUMIF('시간 근거'!$A$2:$A$546,D33,'시간 근거'!$E$2:$E$546) -> 30 | I33: =SUMIF('시간 근거'!$A$2:$A$546,D33,'시간 근거'!$F$2:$F$546) -> 45 | J33: 25 | K33: 40 | L33: 2라운드를 짧게
A34: 33 | B34: 에이전트 | C34: 이론 | D34: AT3 | E34: AI가 부를 수 있는 기능과, 그 기능을 꽂는 규격 — 도구와 MCP | F34: 비유: 콘센트 규격 · 도구 = 이름 · 받는 것 · 돌려주는 것 · 설명 · 규격이 왜 필요한가 · 연결 모양 그림(일꾼 – 서버 – 원천) · 종이 도구 카드 쓰기 | G34: AP1 연결 검사 · AL2~AL4 | H34: =SUMIF('시간 근거'!$A$2:$A$546,D34,'시간 근거'!$E$2:$E$546) -> 30 | I34: =SUMIF('시간 근거'!$A$2:$A$546,D34,'시간 근거'!$F$2:$F$546) -> 35 | J34: 25 | K34: 30 | L34: 연결 그림을 짧게
A35: 34 | B35: 에이전트 | C35: 이론 | D35: AT4 | E35: 지금 값은 원천에 물어야 하고, AI에게는 읽기만 맡긴다 | F35: 비유: 냉장고 재고는 열어 봐야 안다 · 고정 지식 vs 지금 값 · 읽는 도구 vs 바꾸는 도구 — 왜 AI는 읽기만, 바꾸기는 승인 뒤 시스템이 · 종이: "오늘 우산 필요?" 원천 고르기 | G35: AP1 · AL2 · AL4 · BL2 | H35: =SUMIF('시간 근거'!$A$2:$A$546,D35,'시간 근거'!$E$2:$E$546) -> 25 | I35: =SUMIF('시간 근거'!$A$2:$A$546,D35,'시간 근거'!$F$2:$F$546) -> 25 | J35: 20 | K35: 20 | L35: 원천 고르기를 시연으로
A36: 35 | B36: 에이전트 | C36: 이론 | D36: AT5 | E36: 선배의 체크리스트가 일하는 순서를 바꾼다 — 작업 요령(스킬) | F36: 비유: 선배의 체크리스트 · 요령 vs 도구 · 요령이 순서를 바꾸는 예(전 · 후 그림) · 종이: "맛집 고르는 요령" 다섯 줄 | G36: AP1 요령 붙이기 · AL5 | H36: =SUMIF('시간 근거'!$A$2:$A$546,D36,'시간 근거'!$E$2:$E$546) -> 30 | I36: =SUMIF('시간 근거'!$A$2:$A$546,D36,'시간 근거'!$F$2:$F$546) -> 30 | J36: 25 | K36: 25 | L36: 예를 짧게
A37: 36 | B37: 에이전트 | C37: 이론 | D37: AT6 | E37: 매번 같아야 하는 판단은 규칙이 맡고, AI는 근거를 모아 설명한다 | F37: 비유: 신호등 · 회사 경비 규정 · 규칙과 AI의 역할 나누기 · 금지 · 경고 · 감점 · 근거 없으면 멈추기(보류) · demo.bpmn.io DMN 두 번째 사용: 경비 규정에 한 줄 더하기 | G37: AP2~AP4 카드 · AL6 | H37: =SUMIF('시간 근거'!$A$2:$A$546,D37,'시간 근거'!$E$2:$E$546) -> 30 | I37: =SUMIF('시간 근거'!$A$2:$A$546,D37,'시간 근거'!$F$2:$F$546) -> 30 | J37: 25 | K37: 30 | L37: DMN을 시연으로
A38: 37 | B38: 에이전트 | C38: 이론 | D38: AT7 | E38: 점수가 아니라 돈으로 비교하고, 값이 바뀌면 언제 뒤집히는지 본다 — 손익 · What-if · 예측 | F38: 비유: 내비게이션 경로(빠른 길 vs 통행료) · 돈으로 비교 · 예측(앞으로 어떻게 될지) · 종이 계산: 택시 vs 지하철, 값 하나 바꿔 뒤집히는 경계 | G38: AP2~AP4 What-if · AL6 | H38: =SUMIF('시간 근거'!$A$2:$A$546,D38,'시간 근거'!$E$2:$E$546) -> 30 | I38: =SUMIF('시간 근거'!$A$2:$A$546,D38,'시간 근거'!$F$2:$F$546) -> 30 | J38: 25 | K38: 25 | L38: 종이 계산을 시연으로
A39: 38 | B39: 에이전트 | C39: 이론 | D39: AT8 | E39: AI 판단은 흔들린다 — 정답표를 먼저 쓰고 채점한다 | F39: 같은 질문 다섯 번의 결과 사례 그림 · 왜 흔들리나 · 정답표(원인 · 1순위 · 빠질 것) · 종이로 정답표 한 줄 | G39: AP2 채점 · AL7 | H39: =SUMIF('시간 근거'!$A$2:$A$546,D39,'시간 근거'!$E$2:$E$546) -> 25 | I39: =SUMIF('시간 근거'!$A$2:$A$546,D39,'시간 근거'!$F$2:$F$546) -> 25 | J39: 20 | K39: 20 | L39: 사례를 짧게
A40: 39 | B40: 에이전트 | C40: 이론 | D40: AR | E40: 지금까지 배운 것 — 포털에 들어가기 전 한 장으로 | F40: 여덟 가지 개념을 한 장으로 · 포털에서 어디에 보이는지 예고 | H40: =SUMIF('시간 근거'!$A$2:$A$546,D40,'시간 근거'!$E$2:$E$546) -> 10 | I40: =SUMIF('시간 근거'!$A$2:$A$546,D40,'시간 근거'!$F$2:$F$546) -> 10 | J40: 10 | K40: 10 | L40: 같음
A41: 40 | B41: 에이전트 | C41: 포털 | D41: AP1 | E41: 냉각 긴급 대응 일꾼을 만든다 — 목표 · 도구 · 요령을 정하고 질문해 본다 (A ① 만들기 · 질문하기) | F41: A 처음이라 천천히. 기본 복제 · 이름 · 역할 · 목표("인터록 전에 유온을 내리고 생산 손실 최소") · 도구 서버(hyd-dmn · enterprise · neo4j) 고르기 · 연결 검사 · 요령 cooling-emergency-triage · 질문하기("HYD-01 유온이 오르는 원인 후보는?")와 도구 호출 과정. 다시 설명: 네 부분(AT1) · 규격 · 읽기만(AT3 · AT4) · 체크리스트(AT5) · 되풀이 고리(AT2) | H41: =SUMIF('시간 근거'!$A$2:$A$546,D41,'시간 근거'!$E$2:$E$546) -> 30 | I41: =SUMIF('시간 근거'!$A$2:$A$546,D41,'시간 근거'!$F$2:$F$546) -> 40 | J41: 25 | K41: 35 | L41: 설명 넷을 둘로 | M41: MCP · GQ
...

Sheet 막별 합계
A1: 막 | B1: 행 수 | C1: 통합 영상 | D1: 통합 오프 | E1: 실전 영상 | F1: 실전 오프
A2: 시작 | B2: =COUNTIF(실라버스!$B$2:$B$70,A2) -> 5 | C2: =SUMIF(실라버스!$B$2:$B$70,$A2,실라버스!$H$2:$H$70) -> 150 | D2: =SUMIF(실라버스!$B$2:$B$70,$A2,실라버스!$I$2:$I$70) -> 160 | E2: =SUMIF(실라버스!$B$2:$B$70,$A2,실라버스!$J$2:$J$70) -> 125 | F2: =SUMIF(실라버스!$B$2:$B$70,$A2,실라버스!$K$2:$K$70) -> 140
A3: 온톨로지 | B3: =COUNTIF(실라버스!$B$2:$B$70,A3) -> 25 | C3: =SUMIF(실라버스!$B$2:$B$70,$A3,실라버스!$H$2:$H$70) -> 855 | D3: =SUMIF(실라버스!$B$2:$B$70,$A3,실라버스!$I$2:$I$70) -> 1020 | E3: =SUMIF(실라버스!$B$2:$B$70,$A3,실라버스!$J$2:$J$70) -> 730 | F3: =SUMIF(실라버스!$B$2:$B$70,$A3,실라버스!$K$2:$K$70) -> 890
A4: 에이전트 | B4: =COUNTIF(실라버스!$B$2:$B$70,A4) -> 21 | C4: =SUMIF(실라버스!$B$2:$B$70,$A4,실라버스!$H$2:$H$70) -> 700 | D4: =SUMIF(실라버스!$B$2:$B$70,$A4,실라버스!$I$2:$I$70) -> 790 | E4: =SUMIF(실라버스!$B$2:$B$70,$A4,실라버스!$J$2:$J$70) -> 600 | F4: =SUMIF(실라버스!$B$2:$B$70,$A4,실라버스!$K$2:$K$70) -> 695
A5: BPMN | B5: =COUNTIF(실라버스!$B$2:$B$70,A5) -> 17 | C5: =SUMIF(실라버스!$B$2:$B$70,$A5,실라버스!$H$2:$H$70) -> 545 | D5: =SUMIF(실라버스!$B$2:$B$70,$A5,실라버스!$I$2:$I$70) -> 675 | E5: =SUMIF(실라버스!$B$2:$B$70,$A5,실라버스!$J$2:$J$70) -> 465 | F5: =SUMIF(실라버스!$B$2:$B$70,$A5,실라버스!$K$2:$K$70) -> 595
A6: 마무리 | B6: =COUNTIF(실라버스!$B$2:$B$70,A6) -> 1 | C6: =SUMIF(실라버스!$B$2:$B$70,$A6,실라버스!$H$2:$H$70) -> 50 | D6: =SUMIF(실라버스!$B$2:$B$70,$A6,실라버스!$I$2:$I$70) -> 50 | E6: =SUMIF(실라버스!$B$2:$B$70,$A6,실라버스!$J$2:$J$70) -> 50 | F6: =SUMIF(실라버스!$B$2:$B$70,$A6,실라버스!$K$2:$K$70) -> 50
A7: 합계 | B7: =SUM(B2:B6) -> 69 | C7: =SUM(C2:C6) -> 2300 | D7: =SUM(D2:D6) -> 2695 | E7: =SUM(E2:E6) -> 1970 | F7: =SUM(F2:F6) -> 2370
A8: 고정 합계 | C8: 2640 | D8: 2520 | E8: 1920 | F8: 2280
A9: 차이(합계 − 고정) | C9: =C7-C8 -> -340 | D9: =D7-D8 -> 175 | E9: =E7-E8 -> 50 | F9: =F7-F8 -> 90
A11: 세 막 비율 (목표 온톨로지 40 : 에이전트 35 : BPMN 25)
A12: 온톨로지 | C12: =IFERROR(C3/(C3+C4+C5),0) -> 0.40714286 | D12: =IFERROR(D3/(D3+D4+D5),0) -> 0.41046278 | E12: =IFERROR(E3/(E3+E4+E5),0) -> 0.40668524 | F12: =IFERROR(F3/(F3+F4+F5),0) -> 0.40825688
A13: 에이전트 | C13: =IFERROR(C4/(C3+C4+C5),0) -> 0.33333333 | D13: =IFERROR(D4/(D3+D4+D5),0) -> 0.31790744 | E13: =IFERROR(E4/(E3+E4+E5),0) -> 0.33426184 | F13: =IFERROR(F4/(F3+F4+F5),0) -> 0.31880734
A14: BPMN | C14: =IFERROR(C5/(C3+C4+C5),0) -> 0.25952381 | D14: =IFERROR(D5/(D3+D4+D5),0) -> 0.27162978 | E14: =IFERROR(E5/(E3+E4+E5),0) -> 0.25905292 | F14: =IFERROR(F5/(F3+F4+F5),0) -> 0.27293578

Sheet 시간 근거
A1: 행 ID | B1: 막 | C1: 구간 | D1: 부품 | E1: 통합 영상(분) | F1: 통합 오프(분)
A2: S1 | B2: 시작 | C2: 시작 | D2: 지식 자산화가 왜 필요한가(비유·사례) | E2: 8 | F2: 6
A3: S1 | B3: 시작 | C3: 시작 | D3: Notion 첫 사용: 로그인·화면 둘러보기 | E3: 5 | F3: 8
A4: S1 | B4: 시작 | C4: 시작 | D4: 노트 틀 복제·칸 설명 따라 하기 | E4: 8 | F4: 8
A5: S1 | B5: 시작 | C5: 시작 | D5: 첫 기록 써 보기 | E5: 5 | F5: 6
A6: S1 | B6: 시작 | C6: 시작 | D6: 막마다 노트 쓰는 법 | E6: 4 | F6: 4
A7: S1 | B7: 시작 | C7: 시작 | D7: 여유: 계정·초대 문제 풀기 | E7: 0 | F7: 6
A8: S1 | B8: 시작 | C8: 시작 | D8: 정리 | E8: 0 | F8: 2
A9: S2 | B9: 시작 | C9: 시작 | D9: 앞 과정 지도 되짚기 | E9: 10 | F9: 8
A10: S2 | B10: 시작 | C10: 시작 | D10: SCADA 화면·실시간 모니터링에서 같은 값 찾기 | E10: 10 | F10: 10
A11: S2 | B11: 시작 | C11: 시작 | D11: 우리 공장 센서와 세 사건 잇기 | E11: 7 | F11: 7
A12: S2 | B12: 시작 | C12: 시작 | D12: 정리 퀴즈 | E12: 3 | F12: 5
A13: S3 | B13: 시작 | C13: 시작 | D13: 건물 층 비유로 보는 포털 구조 | E13: 10 | F13: 8
... A546: E1 | B546: 마무리 | C546: 마무리 | D546: 질문 | E546: 8 | F546: 8

Sheet 근거 출처
A1: 약칭 | B1: 출처
A2: RAISE | B2: 경보 발생 16~33 s, 쿨러 32.7 s — HANDOFF.md A128(10-07~08)
A3: W4 | B3: 실제 AI 일꾼 4단계 3~4분 — HANDOFF.md A158(.evidence/a158/scenarios/)
A4: CASE | B4: 쿨러 처리 건 전체(일꾼 4작업·승인·PLC·작업지시·종결) 4분 55초 — HANDOFF.md A154 0.4(.evidence/cloud0/)
A5: EXT | B5: 1쪽 문서 추출 Claude Code 127~158 s — HANDOFF.md A098, MANUAL_INGESTION.md:14(A128, .evidence/sessions/09/live/)
A6: GQ | B6: 꼭 답할 질문 3개 일꾼 답 45 s — HANDOFF.md A118
A7: LONG | B7: 80쪽 실물 매뉴얼 612 s·구간 2 — MANUAL_INGESTION.md:13·54(A119)
A8: MCP | B8: MCP 서버 시작(stdio initialize) 17.18 s — HANDOFF.md A032(a032-neo4j-stdio.json)
A9: OIL | B9: 사람 입력 근거 진단 1단계 49 s — HANDOFF.md B7 라이브(A160 앞)
A10: REOBS | B10: 재관측 15분 ÷ 배속 20 = 45 s — CLAUDE.md §3, scenario-research.md §9
A11: WAITB | B11: 정비창·입고 대기: 20배속에서도 정비창 2 h → 6분, 리드타임 2일 → 2.4 h — scenario-research.md §9. 수업 압축 3분 가정(결정 4 미정)
A12: CC | B12: Claude Code 작은 생성 1~3분/지시 — 실측 없음. 가까운 근거: 1쪽 추출 127~158 s(A098·A128), 질문 답 45 s(A118)
A13: BOOT | B13: 스택 기동 268 s — HANDOFF.md A148(학생은 미리 켜 둔 상태로 시작, 수업 시간에 안 넣음)
